2025-07-01 02:37:32,184 ERROR: Exception on / [GET] [in C:\Users\57671.DESKTOP-U9QCETA\desktop\flask mega\venv\Lib\site-packages\flask\app.py:875]
Traceback (most recent call last):
  File "C:\Users\57671.DESKTOP-U9QCETA\desktop\flask mega\venv\Lib\site-packages\flask\app.py", line 1511, in wsgi_app
    response = self.full_dispatch_request()
               ^^^^^^^^^^^^^^^^^^^^^^^^^^^^
  File "C:\Users\57671.DESKTOP-U9QCETA\desktop\flask mega\venv\Lib\site-packages\flask\app.py", line 919, in full_dispatch_request
    rv = self.handle_user_exception(e)
         ^^^^^^^^^^^^^^^^^^^^^^^^^^^^^
  File "C:\Users\57671.DESKTOP-U9QCETA\desktop\flask mega\venv\Lib\site-packages\flask\app.py", line 917, in full_dispatch_request
    rv = self.dispatch_request()
         ^^^^^^^^^^^^^^^^^^^^^^^
  File "C:\Users\57671.DESKTOP-U9QCETA\desktop\flask mega\venv\Lib\site-packages\flask\app.py", line 902, in dispatch_request
    return self.ensure_sync(self.view_functions[rule.endpoint])(**view_args)  # type: ignore[no-any-return]
           ^^^^^^^^^^^^^^^^^^^^^^^^^^^^^^^^^^^^^^^^^^^^^^^^^^^^^^^^^^^^^^^^^
  File "C:\Users\57671.DESKTOP-U9QCETA\desktop\flask mega\venv\Lib\site-packages\flask_login\utils.py", line 290, in decorated_view
    return current_app.ensure_sync(func)(*args, **kwargs)
           ^^^^^^^^^^^^^^^^^^^^^^^^^^^^^^^^^^^^^^^^^^^^^^
  File "C:\Users\57671.DESKTOP-U9QCETA\Desktop\flask mega\app\routes.py", line 40, in index
    return render_template(
           ^^^^^^^^^^^^^^^^
  File "C:\Users\57671.DESKTOP-U9QCETA\desktop\flask mega\venv\Lib\site-packages\flask\templating.py", line 150, in render_template
    return _render(app, template, context)
           ^^^^^^^^^^^^^^^^^^^^^^^^^^^^^^^
  File "C:\Users\57671.DESKTOP-U9QCETA\desktop\flask mega\venv\Lib\site-packages\flask\templating.py", line 131, in _render
    rv = template.render(context)
         ^^^^^^^^^^^^^^^^^^^^^^^^
  File "C:\Users\57671.DESKTOP-U9QCETA\desktop\flask mega\venv\Lib\site-packages\jinja2\environment.py", line 1295, in render
    self.environment.handle_exception()
  File "C:\Users\57671.DESKTOP-U9QCETA\desktop\flask mega\venv\Lib\site-packages\jinja2\environment.py", line 942, in handle_exception
    raise rewrite_traceback_stack(source=source)
  File "C:\Users\57671.DESKTOP-U9QCETA\Desktop\flask mega\app\templates\index.html", line 2, in top-level template code
    {% import "bootstrap_wtf.html" as wtf %}
    ^^^^^^^^^^^^^^^^^^^^^^^^^
  File "C:\Users\57671.DESKTOP-U9QCETA\Desktop\flask mega\app\templates\base.html", line 135, in top-level template code
    const response = await fetch('{{ url_for('main.notifications') }}?since=' + since);
    ^^^^^^^^^^^^^^^^^^^^^^^^^
  File "C:\Users\57671.DESKTOP-U9QCETA\desktop\flask mega\venv\Lib\site-packages\flask\app.py", line 1121, in url_for
    return self.handle_url_build_error(error, endpoint, values)
           ^^^^^^^^^^^^^^^^^^^^^^^^^^^^^^^^^^^^^^^^^^^^^^^^^^^^
  File "C:\Users\57671.DESKTOP-U9QCETA\desktop\flask mega\venv\Lib\site-packages\flask\app.py", line 1110, in url_for
    rv = url_adapter.build(  # type: ignore[union-attr]
         ^^^^^^^^^^^^^^^^^^^^^^^^^^^^^^^^^^^^^^^^^^^^^^
  File "C:\Users\57671.DESKTOP-U9QCETA\desktop\flask mega\venv\Lib\site-packages\werkzeug\routing\map.py", line 924, in build
    raise BuildError(endpoint, values, method, self)
werkzeug.routing.exceptions.BuildError: Could not build url for endpoint 'main.notifications'. Did you mean 'notifications' instead?
2025-07-01 02:38:01,283 INFO: Microblog startup [in C:\Users\57671.DESKTOP-U9QCETA\Desktop\flask mega\app\__init__.py:62]
2025-07-01 02:38:22,101 ERROR: Exception on /user/panjiannan [GET] [in C:\Users\57671.DESKTOP-U9QCETA\desktop\flask mega\venv\Lib\site-packages\flask\app.py:875]
Traceback (most recent call last):
  File "C:\Users\57671.DESKTOP-U9QCETA\desktop\flask mega\venv\Lib\site-packages\flask\app.py", line 1511, in wsgi_app
    response = self.full_dispatch_request()
               ^^^^^^^^^^^^^^^^^^^^^^^^^^^^
  File "C:\Users\57671.DESKTOP-U9QCETA\desktop\flask mega\venv\Lib\site-packages\flask\app.py", line 919, in full_dispatch_request
    rv = self.handle_user_exception(e)
         ^^^^^^^^^^^^^^^^^^^^^^^^^^^^^
  File "C:\Users\57671.DESKTOP-U9QCETA\desktop\flask mega\venv\Lib\site-packages\flask\app.py", line 917, in full_dispatch_request
    rv = self.dispatch_request()
         ^^^^^^^^^^^^^^^^^^^^^^^
  File "C:\Users\57671.DESKTOP-U9QCETA\desktop\flask mega\venv\Lib\site-packages\flask\app.py", line 902, in dispatch_request
    return self.ensure_sync(self.view_functions[rule.endpoint])(**view_args)  # type: ignore[no-any-return]
           ^^^^^^^^^^^^^^^^^^^^^^^^^^^^^^^^^^^^^^^^^^^^^^^^^^^^^^^^^^^^^^^^^
  File "C:\Users\57671.DESKTOP-U9QCETA\desktop\flask mega\venv\Lib\site-packages\flask_login\utils.py", line 290, in decorated_view
    return current_app.ensure_sync(func)(*args, **kwargs)
           ^^^^^^^^^^^^^^^^^^^^^^^^^^^^^^^^^^^^^^^^^^^^^^
  File "C:\Users\57671.DESKTOP-U9QCETA\Desktop\flask mega\app\routes.py", line 105, in user
    return render_template('user.html',
          ^^^^^^^^^^^^^^^^^^^^^^^^^^^^
  File "C:\Users\57671.DESKTOP-U9QCETA\desktop\flask mega\venv\Lib\site-packages\flask\templating.py", line 150, in render_template
    return _render(app, template, context)
           ^^^^^^^^^^^^^^^^^^^^^^^^^^^^^^^
  File "C:\Users\57671.DESKTOP-U9QCETA\desktop\flask mega\venv\Lib\site-packages\flask\templating.py", line 131, in _render
    rv = template.render(context)
         ^^^^^^^^^^^^^^^^^^^^^^^^
  File "C:\Users\57671.DESKTOP-U9QCETA\desktop\flask mega\venv\Lib\site-packages\jinja2\environment.py", line 1295, in render
    self.environment.handle_exception()
  File "C:\Users\57671.DESKTOP-U9QCETA\desktop\flask mega\venv\Lib\site-packages\jinja2\environment.py", line 942, in handle_exception
    raise rewrite_traceback_stack(source=source)
  File "C:\Users\57671.DESKTOP-U9QCETA\Desktop\flask mega\app\templates\user.html", line 1, in top-level template code
    {% extends "base.html" %}
  File "C:\Users\57671.DESKTOP-U9QCETA\Desktop\flask mega\app\templates\base.html", line 75, in top-level template code
    {% block content %}{% endblock %}
    ^^^^^^^^^^^^^^^^^^^^^^^^^
  File "C:\Users\57671.DESKTOP-U9QCETA\Desktop\flask mega\app\templates\user.html", line 32, in block 'content'
    <p><a href="{{ url_for('main.send_message', recipient=user.username) }}">{{ _('Send private message') }}</a></p>
    ^^^^^^^^^^^^^^^^^^^^^^^^^
  File "C:\Users\57671.DESKTOP-U9QCETA\desktop\flask mega\venv\Lib\site-packages\flask\app.py", line 1121, in url_for
    return self.handle_url_build_error(error, endpoint, values)
           ^^^^^^^^^^^^^^^^^^^^^^^^^^^^^^^^^^^^^^^^^^^^^^^^^^^^
  File "C:\Users\57671.DESKTOP-U9QCETA\desktop\flask mega\venv\Lib\site-packages\flask\app.py", line 1110, in url_for
    rv = url_adapter.build(  # type: ignore[union-attr]
         ^^^^^^^^^^^^^^^^^^^^^^^^^^^^^^^^^^^^^^^^^^^^^^
  File "C:\Users\57671.DESKTOP-U9QCETA\desktop\flask mega\venv\Lib\site-packages\werkzeug\routing\map.py", line 924, in build
    raise BuildError(endpoint, values, method, self)
werkzeug.routing.exceptions.BuildError: Could not build url for endpoint 'main.send_message' with values ['recipient']. Did you mean 'send_message' instead?
2025-07-01 02:39:23,530 INFO: Microblog startup [in C:\Users\57671.DESKTOP-U9QCETA\Desktop\flask mega\app\__init__.py:62]
2025-07-01 16:22:27,899 INFO: Microblog startup [in C:\Users\57671.DESKTOP-U9QCETA\Desktop\flask mega\app\__init__.py:62]
