2025-06-27 07:23:31,294 ERROR: Exception on /follow/susan [POST] [in C:\Users\57671.DESKTOP-U9QCETA\desktop\flask mega\venv\Lib\site-packages\flask\app.py:875]
Traceback (most recent call last):
  File "C:\Users\57671.DESKTOP-U9QCETA\desktop\flask mega\venv\Lib\site-packages\sqlalchemy\orm\sync.py", line 117, in populate_dict
    value = source_mapper._get_state_attr_by_column(
            ^^^^^^^^^^^^^^^^^^^^^^^^^^^^^^^^^^^^^^^^
  File "C:\Users\57671.DESKTOP-U9QCETA\desktop\flask mega\venv\Lib\site-packages\sqlalchemy\orm\mapper.py", line 3589, in _get_state_attr_by_column
    prop = self._columntoproperty[column]
           ~~~~~~~~~~~~~~~~~~~~~~^^^^^^^^
  File "C:\Users\57671.DESKTOP-U9QCETA\desktop\flask mega\venv\Lib\site-packages\sqlalchemy\orm\mapper.py", line 4428, in __missing__
    raise orm_exc.UnmappedColumnError(
sqlalchemy.orm.exc.UnmappedColumnError: No column followers.followed_id is configured on mapper Mapper[User(user)]...

The above exception was the direct cause of the following exception:

Traceback (most recent call last):
  File "C:\Users\57671.DESKTOP-U9QCETA\desktop\flask mega\venv\Lib\site-packages\flask\app.py", line 1511, in wsgi_app
    response = self.full_dispatch_request()
               ^^^^^^^^^^^^^^^^^^^^^^^^^^^^
  File "C:\Users\57671.DESKTOP-U9QCETA\desktop\flask mega\venv\Lib\site-packages\flask\app.py", line 919, in full_dispatch_request
    rv = self.handle_user_exception(e)
         ^^^^^^^^^^^^^^^^^^^^^^^^^^^^^
  File "C:\Users\57671.DESKTOP-U9QCETA\desktop\flask mega\venv\Lib\site-packages\flask\app.py", line 917, in full_dispatch_request
    rv = self.dispatch_request()
         ^^^^^^^^^^^^^^^^^^^^^^^
  File "C:\Users\57671.DESKTOP-U9QCETA\desktop\flask mega\venv\Lib\site-packages\flask\app.py", line 902, in dispatch_request
    return self.ensure_sync(self.view_functions[rule.endpoint])(**view_args)  # type: ignore[no-any-return]
           ^^^^^^^^^^^^^^^^^^^^^^^^^^^^^^^^^^^^^^^^^^^^^^^^^^^^^^^^^^^^^^^^^
  File "C:\Users\57671.DESKTOP-U9QCETA\desktop\flask mega\venv\Lib\site-packages\flask_login\utils.py", line 290, in decorated_view
    return current_app.ensure_sync(func)(*args, **kwargs)
           ^^^^^^^^^^^^^^^^^^^^^^^^^^^^^^^^^^^^^^^^^^^^^^
  File "C:\Users\57671.DESKTOP-U9QCETA\Desktop\flask mega\app\routes.py", line 116, in follow
    db.session.commit()
  File "C:\Users\57671.DESKTOP-U9QCETA\desktop\flask mega\venv\Lib\site-packages\sqlalchemy\orm\scoping.py", line 599, in commit
    return self._proxied.commit()
           ^^^^^^^^^^^^^^^^^^^^^^
  File "C:\Users\57671.DESKTOP-U9QCETA\desktop\flask mega\venv\Lib\site-packages\sqlalchemy\orm\session.py", line 2032, in commit
    trans.commit(_to_root=True)
  File "<string>", line 2, in commit
  File "C:\Users\57671.DESKTOP-U9QCETA\desktop\flask mega\venv\Lib\site-packages\sqlalchemy\orm\state_changes.py", line 139, in _go
    ret_value = fn(self, *arg, **kw)
                ^^^^^^^^^^^^^^^^^^^^
  File "C:\Users\57671.DESKTOP-U9QCETA\desktop\flask mega\venv\Lib\site-packages\sqlalchemy\orm\session.py", line 1313, in commit
    self._prepare_impl()
  File "<string>", line 2, in _prepare_impl
  File "C:\Users\57671.DESKTOP-U9QCETA\desktop\flask mega\venv\Lib\site-packages\sqlalchemy\orm\state_changes.py", line 139, in _go
    ret_value = fn(self, *arg, **kw)
                ^^^^^^^^^^^^^^^^^^^^
  File "C:\Users\57671.DESKTOP-U9QCETA\desktop\flask mega\venv\Lib\site-packages\sqlalchemy\orm\session.py", line 1288, in _prepare_impl
    self.session.flush()
  File "C:\Users\57671.DESKTOP-U9QCETA\desktop\flask mega\venv\Lib\site-packages\sqlalchemy\orm\session.py", line 4345, in flush
    self._flush(objects)
  File "C:\Users\57671.DESKTOP-U9QCETA\desktop\flask mega\venv\Lib\site-packages\sqlalchemy\orm\session.py", line 4480, in _flush
    with util.safe_reraise():
  File "C:\Users\57671.DESKTOP-U9QCETA\desktop\flask mega\venv\Lib\site-packages\sqlalchemy\util\langhelpers.py", line 224, in __exit__
    raise exc_value.with_traceback(exc_tb)
  File "C:\Users\57671.DESKTOP-U9QCETA\desktop\flask mega\venv\Lib\site-packages\sqlalchemy\orm\session.py", line 4441, in _flush
    flush_context.execute()
  File "C:\Users\57671.DESKTOP-U9QCETA\desktop\flask mega\venv\Lib\site-packages\sqlalchemy\orm\unitofwork.py", line 466, in execute
    rec.execute(self)
  File "C:\Users\57671.DESKTOP-U9QCETA\desktop\flask mega\venv\Lib\site-packages\sqlalchemy\orm\unitofwork.py", line 591, in execute
    self.dependency_processor.process_saves(uow, states)
  File "C:\Users\57671.DESKTOP-U9QCETA\desktop\flask mega\venv\Lib\site-packages\sqlalchemy\orm\dependency.py", line 1152, in process_saves
    if not self._synchronize(
           ^^^^^^^^^^^^^^^^^^
  File "C:\Users\57671.DESKTOP-U9QCETA\desktop\flask mega\venv\Lib\site-packages\sqlalchemy\orm\dependency.py", line 1285, in _synchronize
    sync.populate_dict(
  File "C:\Users\57671.DESKTOP-U9QCETA\desktop\flask mega\venv\Lib\site-packages\sqlalchemy\orm\sync.py", line 121, in populate_dict
    _raise_col_to_prop(False, source_mapper, l, None, r, err)
  File "C:\Users\57671.DESKTOP-U9QCETA\desktop\flask mega\venv\Lib\site-packages\sqlalchemy\orm\sync.py", line 157, in _raise_col_to_prop
    raise exc.UnmappedColumnError(
sqlalchemy.orm.exc.UnmappedColumnError: Can't execute sync rule for source column 'followers.followed_id'; mapper 'Mapper[User(user)]' does not map this column.  Try using an explicit `foreign_keys` collection which does not include destination column 'user.id' (or use a viewonly=True relation).
2025-06-27 07:27:50,427 INFO: Microblog startup [in C:\Users\57671.DESKTOP-U9QCETA\Desktop\flask mega\app\__init__.py:44]
2025-06-27 07:58:50,548 INFO: Microblog startup [in C:\Users\57671.DESKTOP-U9QCETA\Desktop\flask mega\app\__init__.py:44]
2025-06-27 23:17:24,149 INFO: Microblog startup [in C:\Users\57671.DESKTOP-U9QCETA\Desktop\flask mega\app\__init__.py:44]
2025-06-27 23:47:47,716 INFO: Microblog startup [in C:\Users\57671.DESKTOP-U9QCETA\Desktop\flask mega\app\__init__.py:44]
2025-06-27 23:47:56,368 ERROR: Exception on / [GET] [in C:\Users\57671.DESKTOP-U9QCETA\desktop\flask mega\venv\Lib\site-packages\flask\app.py:875]
Traceback (most recent call last):
  File "C:\Users\57671.DESKTOP-U9QCETA\desktop\flask mega\venv\Lib\site-packages\flask\app.py", line 1511, in wsgi_app
    response = self.full_dispatch_request()
               ^^^^^^^^^^^^^^^^^^^^^^^^^^^^
  File "C:\Users\57671.DESKTOP-U9QCETA\desktop\flask mega\venv\Lib\site-packages\flask\app.py", line 919, in full_dispatch_request
    rv = self.handle_user_exception(e)
         ^^^^^^^^^^^^^^^^^^^^^^^^^^^^^
  File "C:\Users\57671.DESKTOP-U9QCETA\desktop\flask mega\venv\Lib\site-packages\flask\app.py", line 917, in full_dispatch_request
    rv = self.dispatch_request()
         ^^^^^^^^^^^^^^^^^^^^^^^
  File "C:\Users\57671.DESKTOP-U9QCETA\desktop\flask mega\venv\Lib\site-packages\flask\app.py", line 902, in dispatch_request
    return self.ensure_sync(self.view_functions[rule.endpoint])(**view_args)  # type: ignore[no-any-return]
           ^^^^^^^^^^^^^^^^^^^^^^^^^^^^^^^^^^^^^^^^^^^^^^^^^^^^^^^^^^^^^^^^^
  File "C:\Users\57671.DESKTOP-U9QCETA\desktop\flask mega\venv\Lib\site-packages\flask_login\utils.py", line 290, in decorated_view
    return current_app.ensure_sync(func)(*args, **kwargs)
           ^^^^^^^^^^^^^^^^^^^^^^^^^^^^^^^^^^^^^^^^^^^^^^
  File "C:\Users\57671.DESKTOP-U9QCETA\Desktop\flask mega\app\routes.py", line 22, in index
    return render_template(
           ^^^^^^^^^^^^^^^^
  File "C:\Users\57671.DESKTOP-U9QCETA\desktop\flask mega\venv\Lib\site-packages\flask\templating.py", line 149, in render_template
    template = app.jinja_env.get_or_select_template(template_name_or_list)
               ^^^^^^^^^^^^^^^^^^^^^^^^^^^^^^^^^^^^^^^^^^^^^^^^^^^^^^^^^^^
  File "C:\Users\57671.DESKTOP-U9QCETA\desktop\flask mega\venv\Lib\site-packages\jinja2\environment.py", line 1087, in get_or_select_template
    return self.get_template(template_name_or_list, parent, globals)
           ^^^^^^^^^^^^^^^^^^^^^^^^^^^^^^^^^^^^^^^^^^^^^^^^^^^^^^^^^
  File "C:\Users\57671.DESKTOP-U9QCETA\desktop\flask mega\venv\Lib\site-packages\jinja2\environment.py", line 1016, in get_template
    return self._load_template(name, globals)
           ^^^^^^^^^^^^^^^^^^^^^^^^^^^^^^^^^^
  File "C:\Users\57671.DESKTOP-U9QCETA\desktop\flask mega\venv\Lib\site-packages\jinja2\environment.py", line 975, in _load_template
    template = self.loader.load(self, name, self.make_globals(globals))
               ^^^^^^^^^^^^^^^^^^^^^^^^^^^^^^^^^^^^^^^^^^^^^^^^^^^^^^^^
  File "C:\Users\57671.DESKTOP-U9QCETA\desktop\flask mega\venv\Lib\site-packages\jinja2\loaders.py", line 138, in load
    code = environment.compile(source, name, filename)
           ^^^^^^^^^^^^^^^^^^^^^^^^^^^^^^^^^^^^^^^^^^^
  File "C:\Users\57671.DESKTOP-U9QCETA\desktop\flask mega\venv\Lib\site-packages\jinja2\environment.py", line 771, in compile
    self.handle_exception(source=source_hint)
  File "C:\Users\57671.DESKTOP-U9QCETA\desktop\flask mega\venv\Lib\site-packages\jinja2\environment.py", line 942, in handle_exception
    raise rewrite_traceback_stack(source=source)
  File "C:\Users\57671.DESKTOP-U9QCETA\Desktop\flask mega\app\templates\index.html", line 21, in template
    {{% include '_post.html' %}}
    ^^^^^^^^^^^^^^^^^^^^^^^^^
jinja2.exceptions.TemplateSyntaxError: unexpected '%'
